Workbook

Sheet LISEZ-MOI
A1: TABLEAU_PLACETTE | B1: Informations relatives à la placette
A2: ID | B2: Identifiant
A3: DATE | B3: Date du relevé au format jj/mm/aaaa. NB : Le relevé phytosociologique peut avoir été réalisé plus tard que la date indiquée. Les relevés sans date ont été effectués entre le 26/05 et le 02/05
A4: OBS | B4: Observateurs
A5: X_L93 | B5: Coordonnée métrique X (Lambert 93)
A6: Y_L93 | B6: Coordonnée métrique Y (Lambert 93)
A7: PENTE | B7: Classe de pente. 1 = plat ou très faible, 2 = faible pente (<5%), 3 = pente moyenne (5 à 10 %), 4 = forte pente (10 à 30%), 5 = très forte pente (>30%)
A8: EXPO | B8: Exposition (°) calculée à partir du MNT
A9: ALTI | B9: Altitude (m) calculée à partir du MNT
A10: TOPO | B10: Classe de topographie. 1 = vallée, 2 = dépression, 3 = fond de vallon, 4 = bas de versant, 5 = milieu de versant, 6 = haut de versant, 7 = rebord de plateau ou de falaise, 8 = plateau, 9 = sommet
A11: G | B11: Surface terrière (m²/ha) mesurée à partir d’un tour relascopique au centre de la placette. Certaines données sont manquantes
A12: STC | B12: Classe de structure forestière (voir CLASSES_Structure)
... A56: Taux d’abroutissement | B56: Taux d’abroutissement de l’espèce sur la sous-placette de 38,5 m² (voir CALCUL_Taux)

Sheet TABLEAU_Placette
A1: ID | B1: DATE | C1: OBS | D1: X_L93 | E1: Y_L93 | F1: PENTE | G1: EXPO | H1: ALTI | I1: TOPO | J1: G | K1: STC | L1: REC_ARBO | M1: REC_ARBU | N1: REC_HERBA | O1: TRAN_NS_FECES | P1: TRAN_NS_FROT | Q1: TRAN_NS_ECOR | R1: TRAN_EO_FECES | S1: TRAN_EO_FROT | T1: TRAN_EO_ECOR | U1: POSI_SP1 | V1: POSI_SP2 | W1: POSI_SP3 | X1: PPL | Y1: UNI | Z1: REAL_PHYTO | AA1: REMARQUES | AB1: PROP_FORET_250 | AC1: PROP_FORET_500 | AD1: PROP_PRAIRIES_250 | AE1: PROP_PRAIRIES_500 | AF1: DIST_DEP | AG1: DIST_COM | AH1: DIST_GR | AI1: DIST_COURS_EAU | AJ1: PROP_FOR_ANC_500 | AK1: DIST_BAT | AL1: SURF_BAT_250 | AM1: SURF_BAT_500 | AN1: BHC_HI_2024 | AO1: DETH_HI_2024 | AP1: ETP_HI_2024 | AQ1: PREC_HI_2024 | AR1: RUTH_HI_2024 | AS1: TMAX_HI_2024 | AT1: TMIN_HI_2024 | AU1: TMOY_HI_2024 | AV1: PRELEV_CHEVREUIL_100HA | AW1: PRELEV_BICHES_100HA | AX1: PRELEV_CERF_ELAPHE_100HA | AY1: ZONE | AZ1: ZONE2 | BA1: DIST_LISIERE
A2: F1 | B2: 46122 | C2: Gabin Laville | D2: 687188.2 | E2: 6408711.7 | F2: 2 | G2: 45 | H2: 992 | I2: 5 | K2: FR | L2: 5 | M2: 3 | N2: 4 | O2: 0 | P2: 0 | Q2: 0 | R2: 0 | S2: 0 | T2: 0 | U2: Nord | V2: Sud | W2: Est | X2: HET | Y2: HET | Z2: =IF(ISNUMBER(MATCH(A2, TABLEAU_Floristique!B$1:DC$1, 0)), "OUI","NON") -> OUI | AB2: 0.63028 | AC2: 0.30881 | AD2: 0.5065897 | AE2: 0.82941566 | AF2: 793.7768 | AG2: 491.34709 | AH2: 18815.412 | AI2: 110.39177 | AJ2: 0.14228 | AK2: 346.27473 | AM2: 1509.6065 | AN2: 788 | AO2: 0 | AP2: 180 | AQ2: 2927 | AR2: 587 | AS2: 73 | AT2: 2 | AU2: 36 | AV2: 0.72789 | AW2: 0.0065 | AX2: 0.05199 | AY2: AUTRE | AZ2: VIADENE | BA2: 78.900673
A3: F10 | B3: 46120 | C3: Gabin Laville | D3: 692623.4 | E3: 6389721.9 | F3: 4 | G3: 353.21103 | H3: 970 | I3: 5 | K3: T | L3: 5 | M3: 5 | N3: 1 | O3: 3 | P3: 1 | Q3: 0 | R3: 3 | S3: 0 | T3: 0 | U3: Nord | V3: Sud | W3: Est | X3: MIX | Y3: FEU | Z3: =IF(ISNUMBER(MATCH(A3, TABLEAU_Floristique!B$1:DC$1, 0)), "OUI","NON") -> OUI | AB3: 0.6268 | AC3: 0.33572 | AD3: 0.42339992 | AE3: 0.63300644 | AF3: 568.80197 | AG3: 481.81069 | AH3: 2078.8406 | AI3: 57.450983 | AJ3: 0.05796 | AK3: 358.60857 | AM3: 703.0367 | AN3: 724 | AO3: 0 | AP3: 194 | AQ3: 2748 | AR3: 746 | AS3: 78 | AT3: -1 | AU3: 38 | AV3: 0.12987 | AW3: 1 | AX3: 3.33766 | AY3: BORALDES | AZ3: BORALDE_OUEST | BA3: 73.167107
A4: F100 | B4: 46175 | C4: Simon Chollet, Gabin Laville | D4: 688363.35 | E4: 6388081.3 | F4: 5 | G4: 220.10091 | H4: 786 | I4: 6 | K4: FI | L4: 4 | M4: 1 | N4: 2 | O4: 0 | P4: 0 | Q4: 0 | R4: 0 | S4: 0 | T4: 0 | U4: Nord | V4: Sud | W4: Est | X4: CHE | Y4: FEU | Z4: =IF(ISNUMBER(MATCH(A4, TABLEAU_Floristique!B$1:DC$1, 0)), "OUI","NON") -> OUI | AB4: 0.89396 | AC4: 0.83438 | AD4: 0.1060022 | AE4: 0.17689716 | AF4: 1156.7317 | AG4: 781.731 | AH4: 3876.5287 | AI4: 209.05104 | AJ4: 0.19687 | AK4: 923.20392 | AN4: 731 | AO4: 0 | AP4: 214 | AQ4: 2847 | AR4: 755 | AS4: 87 | AT4: 4 | AU4: 45 | AV4: 1.13314 | AW4: 0.7409 | AX4: 2.39704 | AY4: BORALDES | AZ4: BORALDE_OUEST | BA4: 165.89537
A5: F101 | B5: 46175 | C5: Simon Chollet, Gabin Laville | D5: 688363.68 | E5: 6388261 | F5: 2 | G5: 230.29008 | H5: 866 | I5: 7 | K5: MTF | L5: 5 | M5: 4 | N5: 2 | O5: 0 | P5: 0 | Q5: 0 | R5: 0 | S5: 0 | T5: 0 | U5: Nord | V5: Sud | W5: Est | X5: CHA | Y5: FEU | Z5: =IF(ISNUMBER(MATCH(A5, TABLEAU_Floristique!B$1:DC$1, 0)), "OUI","NON") -> OUI | AB5: 0.65804 | AC5: 0.69717 | AD5: 0.34588849 | AE5: 0.31182683 | AF5: 1307.6995 | AG5: 619.0306 | AH5: 4038.3033 | AI5: 222.83144 | AJ5: 0.06885 | AK5: 904.52316 | AN5: 731 | AO5: 0 | AP5: 214 | AQ5: 2847 | AR5: 755 | AS5: 87 | AT5: 4 | AU5: 45 | AV5: 1.13314 | AW5: 0.7409 | AX5: 2.39704 | AY5: BORALDES | AZ5: BORALDE_OUEST | BA5: 2.026297
A6: F102 | B6: 46175 | C6: Simon Chollet, Gabin Laville | D6: 686966.69 | E6: 6389989.3 | F6: 4 | G6: 321.84277 | H6: 812 | I6: 6 | K6: FI | L6: 5 | M6: 3 | N6: 1 | O6: 0 | P6: 0 | Q6: 0 | R6: 0 | S6: 0 | T6: 0 | U6: Nord | V6: Sud | W6: Est | X6: HET | Y6: HET | Z6: =IF(ISNUMBER(MATCH(A6, TABLEAU_Floristique!B$1:DC$1, 0)), "OUI","NON") -> OUI | AB6: 0.99205 | AC6: 0.96551 | AD6: 0.0013326081 | AE6: 0.032140366 | AF6: 1913.8303 | AG6: 452.97227 | AH6: 6219.1436 | AI6: 259.45895 | AJ6: 0.92871 | AK6: 877.95576 | AN6: 726 | AO6: 0 | AP6: 231 | AQ6: 2866 | AR6: 543 | AS6: 90 | AT6: 3 | AU6: 48 | AV6: 0.30278 | AW6: 0.16515 | AX6: 0.68814 | AY6: BORALDES | AZ6: BORALDE_OUEST | BA6: 238.98712
A7: F103 | B7: 46175 | C7: Simon Chollet, Gabin Laville | D7: 687155.61 | E7: 6389715.5 | F7: 4 | G7: 166.09732 | H7: 752 | I7: 5 | K7: FI | L7: 5 | M7: 5 | N7: 2 | O7: 0 | P7: 0 | Q7: 0 | R7: 0 | S7: 0 | T7: 0 | U7: Nord | V7: Sud | W7: Est | X7: FEU | Y7: FEU | Z7: =IF(ISNUMBER(MATCH(A7, TABLEAU_Floristique!B$1:DC$1, 0)), "OUI","NON") -> OUI | AB7: 0.99801 | AC7: 0.96783 | AE7: 0.029358544 | AF7: 2012.1493 | AG7: 137.54448 | AH7: 5887.6378 | AI7: 165.33785 | AJ7: 0.95093 | AK7: 914.54582 | AN7: 733 | AO7: 0 | AP7: 217 | AQ7: 2866 | AR7: 656 | AS7: 88 | AT7: 4 | AU7: 47 | AV7: 0.30278 | AW7: 0.16515 | AX7: 0.68814 | AY7: BORALDES | AZ7: BORALDE_OUEST | BA7: 284.70573
A8: F104 | B8: 46211 | C8: Gabin Laville | D8: 687639.89 | E8: 6390114.3 | F8: 3 | G8: 142.23692 | H8: 748 | I8: 5 | J8: 17 | K8: FI | L8: 4 | M8: 4 | N8: 5 | O8: 0 | P8: 0 | Q8: 0 | R8: 0 | S8: 0 | T8: 0 | U8: Nord | V8: Sud | W8: Est | X8: CHE | Y8: FEU | Z8: =IF(ISNUMBER(MATCH(A8, TABLEAU_Floristique!B$1:DC$1, 0)), "OUI","NON") -> OUI | AB8: 0.97052 | AC8: 0.87814 | AD8: 0.04028076 | AE8: 0.118771 | AF8: 1580.6302 | AG8: 66.180645 | AH8: 6024.98 | AI8: 146.39795 | AJ8: 0.50026 | AK8: 781.17596 | AN8: 733 | AO8: 0 | AP8: 217 | AQ8: 2846 | AR8: 656 | AS8: 88 | AT8: 4 | AU8: 47 | AV8: 0.30278 | AW8: 0.16515 | AX8: 0.68814 | AY8: BORALDES | AZ8: BORALDE_OUEST | BA8: 198.07038
A9: F105 | B9: 46196 | C9: Gabin Laville | D9: 689415.92 | E9: 6391393.9 | F9: 3 | G9: 311.82019 | H9: 920 | I9: 5 | J9: 15 | K9: FI | L9: 5 | M9: 4 | N9: 2 | O9: 0 | P9: 0 | Q9: 0 | R9: 0 | S9: 0 | T9: 0 | U9: Nord | V9: Sud | W9: Est | X9: FEU | Y9: FEU | Z9: =IF(ISNUMBER(MATCH(A9, TABLEAU_Floristique!B$1:DC$1, 0)), "OUI","NON") -> OUI | AB9: 0.61692 | AC9: 0.48215 | AD9: 0.35215009 | AE9: 0.45757318 | AF9: 245.76039 | AG9: 300.51117 | AH9: 5531.8833 | AI9: 301.07193 | AJ9: 0.22995 | AK9: 287.97233 | AM9: 4061.1617 | AN9: 747 | AO9: 0 | AP9: 190 | AQ9: 2825 | AR9: 733 | AS9: 76 | AT9: 6 | AU9: 38 | AV9: 1.13314 | AW9: 0.7409 | AX9: 2.39704 | AY9: BORALDES | AZ9: BORALDE_OUEST | BA9: 34.981955
A10: F106 | B10: 46190 | C10: Gabin Laville | D10: 696205.09 | E10: 6394209.8 | F10: 2 | G10: 239.03624 | H10: 1343 | I10: 5 | J10: 25 | K10: MTF | L10: 5 | M10: 4 | N10: 2 | O10: 0 | P10: 0 | Q10: 0 | R10: 0 | S10: 0 | T10: 0 | U10: Nord | V10: Sud | W10: Est | X10: MIX | Y10: HET | Z10: =IF(ISNUMBER(MATCH(A10, TABLEAU_Floristique!B$1:DC$1, 0)), "OUI","NON") -> OUI | AB10: 1 | AC10: 0.99639 | AE10: 0.0049399431 | AF10: 696.27374 | AG10: 919.29076 | AH10: 2732.8237 | AI10: 440.59639 | AJ10: 1 | AK10: 970.92298 | AN10: 761 | AO10: 0 | AP10: 121 | AQ10: 2660 | AR10: 827 | AS10: 51 | AT10: -3 | AU10: 22 | AV10: 1.13314 | AW10: 0.7409 | AX10: 2.39704 | AY10: BORALDES | AZ10: PLATEAU | BA10: 449.65969
A11: F107bis | B11: 46211 | C11: Gabin Laville | D11: 690189.5 | E11: 6386932.4 | F11: 5 | G11: 197.48801 | H11: 829 | I11: 3 | J11: 14 | K11: FI | L11: 4 | M11: 5 | N11: + | O11: 0 | P11: 0 | Q11: 0 | R11: 0 | S11: 0 | T11: 0 | U11: Nord | V11: Sud | W11: Est | X11: FEU | Y11: FEU | Z11: =IF(ISNUMBER(MATCH(A11, TABLEAU_Floristique!B$1:DC$1, 0)), "OUI","NON") -> OUI | AB11: 0.87533 | AC11: 0.58279 | AD11: 0.13670654 | AE11: 0.40623524 | AF11: 569.29655 | AG11: 400.17588 | AH11: 2268.3802 | AI11: 191.01581 | AJ11: 0.03616 | AK11: 355.38475 | AM11: 1202.519 | AN11: 719 | AO11: 0 | AP11: 212 | AQ11: 2807 | AR11: 602 | AS11: 81 | AT11: 5 | AU11: 43 | AV11: 0.12987 | AW11: 1 | AX11: 3.33766 | AY11: BORALDES | AZ11: BORALDE_CENTRE | BA11: 134.71576
A12: F11 | B12: 46120 | C12: Gabin Laville | D12: 693285.69 | E12: 6387986.1 | F12: 5 | G12: 183.42387 | H12: 884 | I12: 5 | K12: MTF | L12: 5 | M12: 3 | N12: 4 | O12: 0 | P12: 0 | Q12: 0 | R12: 0 | S12: 2 | T12: 0 | U12: Nord | V12: Sud | W12: Est | X12: CHE | Y12: FEU | Z12: =IF(ISNUMBER(MATCH(A12, TABLEAU_Floristique!B$1:DC$1, 0)), "OUI","NON") -> OUI | AB12: 0.4989 | AC12: 0.27906 | AD12: 0.50115837 | AE12: 0.64848111 | AF12: 97.870614 | AG12: 63.559777 | AH12: 494.58733 | AI12: 189.77477 | AK12: 233.0186 | AL12: 296.29749 | AM12: 15611.304 | AN12: 691 | AO12: 0 | AP12: 221 | AQ12: 2750 | AR12: 733 | AS12: 85 | AT12: -3 | AU12: 45 | AV12: 0.12987 | AW12: 1 | AX12: 3.33766 | AY12: BORALDES | AZ12: BORALDE_CENTRE | BA12: 60.173069
A13: F12 | B13: 46121 | C13: Gabin Laville | D13: 697665.69 | E13: 6388912.3 | F13: 2 | G13: 316.50745 | H13: 1096 | I13: 5 | K13: FI | L13: 5 | M13: 4 | N13: 2 | O13: 0 | P13: 0 | Q13: 0 | R13: 0 | S13: 0 | T13: 0 | U13: Nord | V13: Sud | W13: Est | X13: FEU | Y13: FEU | Z13: =IF(ISNUMBER(MATCH(A13, TABLEAU_Floristique!B$1:DC$1, 0)), "OUI","NON") -> OUI | AB13: 0.82532 | AC13: 0.65262 | AD13: 0.33975266 | AE13: 0.40900348 | AF13: 574.98355 | AG13: 229.04145 | AH13: 1294.0558 | AI13: 452.08804 | AJ13: 0.48325 | AK13: 311.33499 | AM13: 2380.0143 | AN13: 719 | AO13: 0 | AP13: 164 | AQ13: 2647 | AR13: 483 | AS13: 73 | AT13: -6 | AU13: 33 | AV13: 0.12987 | AW13: 1 | AX13: 3.33766 | AY13: BORALDES | AZ13: PLATEAU | BA13: 56.427462
A14: F13 | B14: 46121 | C14: Gabin Laville | D14: 697953.27 | E14: 6389086 | F14: 4 | G14: 277.59467 | H14: 1159 | I14: 5 | K14: MTF | L14: 5 | M14: 4 | N14: 2 | O14: 4 | P14: 0 | Q14: 0 | R14: 4 | S14: 0 | T14: 0 | U14: Nord | V14: Sud | W14: Est | X14: FEU | Y14: FEU | Z14: =IF(ISNUMBER(MATCH(A14, TABLEAU_Floristique!B$1:DC$1, 0)), "OUI","NON") -> OUI | AB14: 0.662 | AC14: 0.74396 | AD14: 0.43517249 | AE14: 0.39147378 | AF14: 781.53942 | AG14: 365.97052 | AH14: 1323.8373 | AI14: 641.03187 | AJ14: 0.43566 | AK14: 190.95078 | AL14: 81.13927 | AM14: 1711.0642 | AN14: 719 | AO14: 0 | AP14: 164 | AQ14: 2642 | AR14: 483 | AS14: 73 | AT14: -6 | AU14: 33 | AV14: 0.12987 | AW14: 1 | AX14: 3.33766 | AY14: BORALDES | AZ14: PLATEAU | BA14: 73.976918
A15: F14 | B15: 46121 | C15: Gabin Laville | D15: 696517.51 | E15: 6388397.3 | F15: 2 | G15: 326.30994 | H15: 1028 | I15: 5 | K15: FI | L15: 5 | M15: 4 | N15: 1 | O15: 0 | P15: 0 | Q15: 0 | R15: 0 | S15: 0 | T15: 0 | U15: Nord | V15: Sud | W15: Est | X15: HET | Y15: HET | Z15: =IF(ISNUMBER(MATCH(A15, TABLEAU_Floristique!B$1:DC$1, 0)), "OUI","NON") -> OUI | AB15: 0.84324 | AC15: 0.75453 | AD15: 0.161258 | AE15: 0.22619459 | AF15: 329.04605 | AG15: 67.25002 | AH15: 779.52854 | AI15: 241.7333 | AJ15: 0.01053 | AK15: 481.89631 | AM15: 296.32047 | AN15: 730 | AO15: 0 | AP15: 162 | AQ15: 2688 | AR15: 510 | AS15: 72 | AT15: 0 | AU15: 32 | AV15: 0.12987 | AW15: 1 | AX15: 3.33766 | AY15: BORALDES | AZ15: BORALDE_CENTRE | BA15: 53.360723
A16: F15 | B16: 46211 | C16: Gabin Laville | D16: 691955.13 | E16: 6382589.7 | F16: 4 | G16: 299.57782 | H16: 625 | I16: 5 | J16: 21 | K16: MTF | L16: 5 | M16: 3 | N16: + | O16: 0 | P16: 0 | Q16: 0 | R16: 0 | S16: 0 | T16: 0 | U16: Nord | V16: Sud | W16: Est | X16: FEU | Y16: FEU | Z16: =IF(ISNUMBER(MATCH(A16, TABLEAU_Floristique!B$1:DC$1, 0)), "OUI","NON") -> OUI | AB16: 0.915 | AC16: 0.75437 | AD16: 0.23093616 | AE16: 0.31002339 | AF16: 676.62211 | AG16: 162.46514 | AH16: 2167.0895 | AI16: 110.27934 | AJ16: 0.26911 | AK16: 235.94452 | AL16: 122.36872 | AM16: 3474.4339 | AN16: 669 | AO16: 0 | AP16: 254 | AQ16: 2762 | AR16: 507 | AS16: 97 | AT16: 6 | AU16: 54 | AV16: 0.52851 | AW16: 1.44645 | AX16: 4.97914 | AY16: BORALDES | AZ16: BORALDE_CENTRE | BA16: 118.71742
A17: F16 | B17: 46211 | C17: Gabin Laville | D17: 692082.49 | E17: 6383426.6 | F17: 5 | G17: 305.53766 | H17: 720 | I17: 5 | J17: 24 | K17: T | L17: 5 | M17: 4 | N17: + | O17: 0 | P17: 0 | Q17: 0 | R17: 0 | S17: 0 | T17: 0 | U17: Nord | V17: Sud | W17: Est | X17: HET | Y17: HET | Z17: =IF(ISNUMBER(MATCH(A17, TABLEAU_Floristique!B$1:DC$1, 0)), "OUI","NON") -> OUI | AB17: 0.47828 | AC17: 0.53746 | AD17: 0.54507691 | AE17: 0.4721284 | AF17: 1326.3099 | AG17: 381.07322 | AH17: 1576.4442 | AI17: 257.54536 | AJ17: 0.13678 | AK17: 382.85651 | AM17: 987.48594 | AN17: 669 | AO17: 0 | AP17: 254 | AQ17: 2763 | AR17: 507 | AS17: 97 | AT17: 6 | AU17: 54 | AV17: 0.52851 | AW17: 1.44645 | AX17: 4.97914 | AY17: BORALDES | AZ17: BORALDE_CENTRE | BA17: 17.515416
A18: F17 | B18: 46121 | C18: Gabin Laville | D18: 698385.64 | E18: 6385922 | F18: 2 | G18: 199.79887 | H18: 1024 | I18: 7 | K18: FR | L18: 4 | M18: 3 | N18: 5 | O18: 0 | P18: 0 | Q18: 0 | R18: 0 | S18: 0 | T18: 0 | U18: Nord | V18: Sud | W18: Est | X18: CHE | Y18: FEU | Z18: =IF(ISNUMBER(MATCH(A18, TABLEAU_Floristique!B$1:DC$1, 0)), "OUI","NON") -> OUI | AB18: 0.81538 | AC18: 0.89144 | AD18: 0.19231889 | AE18: 0.13211385 | AF18: 179.81778 | AG18: 200.49861 | AH18: 3878.8578 | AI18: 205.94532 | AJ18: 0.36581 | AK18: 208.57514 | AL18: 206.50211 | AM18: 2045.9897 | AN18: 693 | AO18: 0 | AP18: 187 | AQ18: 2654 | AR18: 609 | AS18: 77 | AT18: -8 | AU18: 36 | AV18: 0.12987 | AW18: 1 | AX18: 3.33766 | AY18: BORALDES | AZ18: BORALDE_CENTRE | BA18: 27.907793
A19: F18 | B19: 46114 | C19: Gabin Laville | D19: 690442.29 | E19: 6412993.2 | F19: 1 | G19: 147.09476 | H19: 1041 | I19: 8 | K19: MTF | L19: 5 | M19: 2 | N19: + | O19: 0 | P19: 0 | Q19: 0 | R19: 0 | S19: 0 | T19: 0 | U19: Nord | V19: Sud | W19: Est | X19: HET | Y19: HET | Z19: =IF(ISNUMBER(MATCH(A19, TABLEAU_Floristique!B$1:DC$1, 0)), "OUI","NON") -> OUI | AB19: 1 | AC19: 0.96871 | AE19: 0.06612161 | AF19: 475.94067 | AG19: 740.9671 | AH19: 20663.333 | AI19: 703.20028 | AJ19: 0.48521 | AK19: 703.3663 | AN19: 763 | AO19: 0 | AP19: 178 | AQ19: 2846 | AR19: 764 | AS19: 71 | AT19: 5 | AU19: 36 | AY19: AUTRE | AZ19: PLATEAU_FERME_NORD | BA19: 300.04237
A20: F19 | B20: 46121 | C20: Gabin Laville | D20: 696277.21 | E20: 6384989.9 | F20: 5 | G20: 231.34019 | H20: 909 | I20: 5 | K20: FI | L20: 4 | M20: 5 | N20: 2 | O20: 0 | P20: 0 | Q20: 0 | R20: 0 | S20: 0 | T20: 0 | U20: Nord | V20: Sud | W20: Est | X20: HET | Y20: HET | Z20: =IF(ISNUMBER(MATCH(A20, TABLEAU_Floristique!B$1:DC$1, 0)), "OUI","NON") -> OUI | AB20: 0.93752 | AC20: 0.64301 | AD20: 0.062849212 | AE20: 0.39324667 | AF20: 736.86607 | AG20: 63.598943 | AH20: 3150.5366 | AI20: 69.010947 | AJ20: 0.40645 | AK20: 817.53625 | AN20: 693 | AO20: 0 | AP20: 200 | AQ20: 2690 | AR20: 619 | AS20: 79 | AT20: -2 | AU20: 39 | AV20: 0.12987 | AW20: 1 | AX20: 3.33766 | AY20: BORALDES | AZ20: BORALDE_CENTRE | BA20: 183.0727
A21: F2 | B21: 46122 | C21: Gabin Laville | D21: 686312.04 | E21: 6408820.9 | F21: 4 | G21: 41.633541 | H21: 929 | I21: 5 | K21: MTF | L21: 5 | M21: 4 | N21: + | O21: 0 | P21: 0 | Q21: 0 | R21: 0 | S21: 0 | T21: 0 | U21: Nord | V21: Sud | W21: Est | X21: MIX | Y21: HET | Z21: =IF(ISNUMBER(MATCH(A21, TABLEAU_Floristique!B$1:DC$1, 0)), "OUI","NON") -> OUI | AB21: 0.66293 | AC21: 0.4833 | AD21: 0.40048733 | AE21: 0.61753703 | AF21: 1135.5063 | AG21: 90.312428 | AH21: 19470.488 | AI21: 65.484296 | AJ21: 0.33492 | AK21: 428.64785 | AM21: 1798.6729 | AN21: 794 | AO21: 0 | AP21: 185 | AQ21: 2958 | AR21: 561 | AS21: 77 | AT21: -1 | AU21: 38 | AV21: 0.72789 | AW21: 0.0065 | AX21: 0.05199 | AY21: AUTRE | AZ21: VIADENE | BA21: 74.559726
A22: F20 | B22: 46126 | C22: Gabin Laville | D22: 696063.93 | E22: 6383747.2 | F22: 5 | G22: 239.62088 | H22: 940 | I22: 6 | K22: FR | L22: 5 | M22: 3 | N22: 2 | O22: 1 | P22: 0 | Q22: 0 | R22: 0 | S22: 0 | T22: 0 | U22: Nord | V22: Sud | W22: Est | X22: PIN | Y22: CON | Z22: =IF(ISNUMBER(MATCH(A22, TABLEAU_Floristique!B$1:DC$1, 0)), "OUI","NON") -> OUI | AB22: 0.76041 | AC22: 0.63819 | AD22: 0.24769487 | AE22: 0.35895468 | AF22: 796.0994 | AG22: 608.23374 | AH22: 3780.0646 | AI22: 410.92874 | AJ22: 0.36969 | AK22: 603.42376 | AN22: 685 | AO22: 0 | AP22: 213 | AQ22: 2692 | AR22: 730 | AS22: 85 | AT22: 0 | AU22: 44 | AV22: 0.64295 | AW22: 0.8144 | AX22: 2.20746 | AY22: BORALDES | AZ22: BORALDE_CENTRE | BA22: 70.724166
A23: F21 | B23: 46126 | C23: Gabin Laville | D23: 695072.18 | E23: 6383579.2 | F23: 4 | G23: 158.35556 | H23: 865 | I23: 5 | K23: FI | L23: 5 | M23: 5 | N23: 3 | O23: 0 | P23: 0 | Q23: 0 | R23: 0 | S23: 0 | T23: 0 | U23: Nord | V23: Sud | W23: Est | X23: FEU | Y23: FEU | Z23: =IF(ISNUMBER(MATCH(A23, TABLEAU_Floristique!B$1:DC$1, 0)), "OUI","NON") -> OUI | AB23: 0.99713 | AC23: 0.78999 | AD23: 0.0059579469 | AE23: 0.21459697 | AF23: 1461.9578 | AG23: 159.21278 | AH23: 3357.0873 | AI23: 348.97949 | AJ23: 0.64796 | AK23: 1035.648 | AN23: 695 | AO23: 0 | AP23: 209 | AQ23: 2710 | AR23: 701 | AS23: 77 | AT23: 9 | AU23: 41 | AV23: 0.12987 | AW23: 1 | AX23: 3.33766 | AY23: BORALDES | AZ23: BORALDE_CENTRE | BA23: 235.60135
A24: F22 | B24: 46122 | C24: Gabin Laville | D24: 694134.89 | E24: 6384287.1 | F24: 5 | G24: 170.53769 | H24: 860 | I24: 5 | K24: MTF | L24: 5 | M24: 3 | N24: 5 | O24: 1 | P24: 0 | Q24: 0 | R24: 2 | S24: 0 | T24: 0 | U24: Sud | V24: Est | W24: Nord | X24: CHE | Y24: FEU | Z24: =IF(ISNUMBER(MATCH(A24, TABLEAU_Floristique!B$1:DC$1, 0)), "OUI","NON") -> OUI | AB24: 0.67453 | AC24: 0.50398 | AD24: 0.28469833 | AE24: 0.4432923 | AF24: 1547.7171 | AG24: 418.59396 | AH24: 2338.6955 | AI24: 105.10399 | AJ24: 0.24552 | AK24: 623.73618 | AN24: 695 | AO24: 0 | AP24: 209 | AQ24: 2726 | AR24: 701 | AS24: 77 | AT24: 9 | AU24: 41 | AV24: 0.12987 | AW24: 1 | AX24: 3.33766 | AY24: BORALDES | AZ24: BORALDE_CENTRE | BA24: 21.381848
A25: F22bis | B25: 46171 | C25: Simon Chollet, Gabin Laville | D25: 694384.77 | E25: 6384563.7 | F25: 3 | G25: 113.87528 | H25: 915 | I25: 7 | K25: FI | L25: 5 | M25: 1 | N25: 4 | O25: 1 | P25: 0 | Q25: 0 | R25: 0 | S25: 0 | T25: 0 | U25: Nord | V25: Sud | W25: Est | X25: CHE | Y25: FEU | Z25: =IF(ISNUMBER(MATCH(A25, TABLEAU_Floristique!B$1:DC$1, 0)), "OUI","NON") -> OUI | AB25: 0.53783 | AC25: 0.43842 | AD25: 0.48811238 | AE25: 0.56978386 | AF25: 1201.483 | AG25: 333.73802 | AH25: 2174.621 | AI25: 101.27106 | AJ25: 0.13962 | AK25: 299.60644 | AM25: 1629.9331 | AN25: 702 | AO25: 0 | AP25: 202 | AQ25: 2726 | AR25: 661 | AS25: 74 | AT25: 9 | AU25: 39 | AV25: 0.12987 | AW25: 1 | AX25: 3.33766 | AY25: BORALDES | AZ25: BORALDE_CENTRE | BA25: 32.666807
A26: F23 | B26: 46121 | C26: Gabin Laville | D26: 698629.26 | E26: 6386288.9 | F26: 3 | G26: 212.98853 | H26: 1078 | I26: 5 | K26: FI | L26: 5 | M26: 4 | N26: 1 | O26: 0 | P26: 0 | Q26: 0 | R26: 0 | S26: 0 | T26: 0 | U26: Nord | V26: Sud | W26: Est | X26: HET | Y26: HET | Z26: =IF(ISNUMBER(MATCH(A26, TABLEAU_Floristique!B$1:DC$1, 0)), "OUI","NON") -> OUI | AB26: 0.97288 | AC26: 0.97882 | AE26: 0.018469515 | AF26: 78.886875 | AG26: 120.43085 | AH26: 3749.0617 | AI26: 274.64292 | AJ26: 0.86696 | AK26: 405.53325 | AM26: 452.76611 | AN26: 693 | AO26: 0 | AP26: 187 | AQ26: 2632 | AR26: 609 | AS26: 77 | AT26: -8 | AU26: 36 | AV26: 0.12987 | AW26: 1 | AX26: 3.33766 | AY26: BORALDES | AZ26: BORALDE_CENTRE | BA26: 334.27411
A27: F24 | B27: 46122 | C27: Gabin Laville | D27: 693580.63 | E27: 6383564.5 | F27: 4 | G27: 90 | H27: 840 | I27: 6 | K27: FI | L27: 5 | M27: 3 | N27: 1 | O27: 0 | P27: 0 | Q27: 0 | R27: 0 | S27: 0 | T27: 0 | U27: Nord | V27: Sud | W27: Est | X27: HET | Y27: HET | Z27: =IF(ISNUMBER(MATCH(A27, TABLEAU_Floristique!B$1:DC$1, 0)), "OUI","NON") -> OUI | AB27: 0.6873 | AC27: 0.58681 | AD27: 0.29367332 | AE27: 0.38121118 | AF27: 2391.426 | AG27: 86.665693 | AH27: 2466.9993 | AI27: 177.96151 | AJ27: 0.26826 | AK27: 156.30404 | AL27: 1693.0285 | AM27: 4357.1823 | AN27: 693 | AO27: 0 | AP27: 216 | AQ27: 2745 | AR27: 591 | AS27: 79 | AT27: 8 | AU27: 43 | AV27: 0.12987 | AW27: 1 | AX27: 3.33766 | AY27: BORALDES | AZ27: BORALDE_CENTRE | BA27: 76.442966
A28: F25 | B28: 46126 | C28: Gabin Laville | D28: 694087.02 | E28: 6383451.1 | F28: 4 | G28: 230.90614 | H28: 858 | I28: 5 | K28: MTF | L28: 5 | M28: 3 | N28: 2 | O28: 1 | P28: 0 | Q28: 0 | R28: 0 | S28: 0 | T28: 0 | U28: Nord | V28: Sud | W28: Est | X28: FEU | Y28: FEU | Z28: =IF(ISNUMBER(MATCH(A28, TABLEAU_Floristique!B$1:DC$1, 0)), "OUI","NON") -> OUI | AB28: 0.87872 | AC28: 0.7772 | AD28: 0.12231398 | AE28: 0.2266271 | AF28: 1973.7588 | AG28: 401.39036 | AH28: 2880.4518 | AI28: 270.40889 | AJ28: 0.35788 | AK28: 607.94931 | AN28: 681 | AO28: 0 | AP28: 230 | AQ28: 2727 | AR28: 576 | AS28: 87 | AT28: 5 | AU28: 47 | AV28: 0.12987 | AW28: 1 | AX28: 3.33766 | AY28: BORALDES | AZ28: BORALDE_CENTRE | BA28: 103.80451
A29: F26 | B29: 46127 | C29: Gabin Laville | D29: 691063.04 | E29: 6383527.9 | F29: 4 | G29: 156.47679 | H29: 767 | I29: 6 | K29: FR | L29: 5 | M29: 2 | N29: 4 | O29: 1 | P29: 0 | Q29: 0 | R29: 2 | S29: 0 | T29: 0 | U29: Sud | V29: Nord | W29: Est | X29: CHE | Y29: FEU | Z29: =IF(ISNUMBER(MATCH(A29, TABLEAU_Floristique!B$1:DC$1, 0)), "OUI","NON") -> NON | AB29: 0.50007 | AC29: 0.44654 | AD29: 0.4885585 | AE29: 0.51684936 | AF29: 1205.2424 | AG29: 152.86615 | AH29: 977.83232 | AI29: 524.80161 | AJ29: 0.1122 | AK29: 359.93503 | AM29: 5745.02 | AN29: 681 | AO29: 0 | AP29: 248 | AQ29: 2789 | AR29: 483 | AS29: 87 | AT29: 12 | AU29: 50 | AV29: 0.52851 | AW29: 1.44645 | AX29: 4.97914 | AY29: BORALDES | AZ29: BORALDE_CENTRE | BA29: 51.928003
A30: F26bis | B30: 46171 | C30: Simon Chollet, Gabin Laville | D30: 690378.48 | E30: 6382869.1 | F30: 3 | G30: 96.499344 | H30: 727 | I30: 5 | J30: 24 | K30: MTF | L30: 5 | M30: 3 | N30: 1 | O30: 0 | P30: 1 | Q30: 0 | R30: 0 | S30: 0 | T30: 0 | U30: Nord | V30: Sud | W30: Est | X30: CHA | Y30: FEU | Z30: =IF(ISNUMBER(MATCH(A30, TABLEAU_Floristique!B$1:DC$1, 0)), "OUI","NON") -> OUI | AB30: 0.27341 | AC30: 0.28873 | AD30: 0.71803504 | AE30: 0.68988627 | AF30: 877.58465 | AG30: 13.666543 | AH30: 1330.0158 | AI30: 488.90681 | AJ30: 0.18777 | AK30: 325.84384 | AM30: 3212.8109 | AN30: 681 | AO30: 0 | AP30: 248 | AQ30: 2800 | AR30: 483 | AS30: 87 | AT30: 12 | AU30: 50 | AV30: 0.52851 | AW30: 1.44645 | AX30: 4.97914 | AY30: BORALDES | AZ30: BORALDE_CENTRE | BA30: 17.165527
A31: F27 | B31: 46127 | C31: Gabin Laville | D31: 689631.79 | E31: 6384628.1 | F31: 5 | G31: 331.63879 | H31: 776 | I31: 6 | K31: FI | L31: 5 | M31: 4 | N31: 2 | O31: 1 | P31: 0 | Q31: 0 | R31: 0 | S31: 0 | T31: 0 | U31: Nord | V31: Est | W31: Sud | X31: HET | Y31: HET | Z31: =IF(ISNUMBER(MATCH(A31, TABLEAU_Floristique!B$1:DC$1, 0)), "OUI","NON") -> OUI | AB31: 0.69627 | AC31: 0.56519 | AD31: 0.30664048 | AE31: 0.41111869 | AF31: 1249.0105 | AG31: 311.38141 | AH31: 312.18505 | AI31: 280.26234 | AJ31: 0.50963 | AK31: 277.7155 | AM31: 6211.4091 | AN31: 709 | AO31: 0 | AP31: 229 | AQ31: 2809 | AR31: 475 | AS31: 92 | AT31: 7 | AU31: 50 | AV31: 0.52851 | AW31: 1.44645 | AX31: 4.97914 | AY31: BORALDES | AZ31: BORALDE_CENTRE | BA31: 72.414664
A32: F28 | B32: 46128 | C32: Gabin Laville | D32: 688134.34 | E32: 6383045.3 | F32: 2 | G32: 259.50854 | H32: 583 | I32: 5 | K32: FI | L32: 5 | M32: 4 | N32: 1 | O32: 0 | P32: 0 | Q32: 0 | R32: 0 | S32: 0 | T32: 0 | U32: Nord | V32: Sud | W32: Est | X32: FEU | Y32: FEU | Z32: =IF(ISNUMBER(MATCH(A32, TABLEAU_Floristique!B$1:DC$1, 0)), "OUI","NON") -> OUI | AB32: 0.98232 | AC32: 0.8618 | AD32: 0.018715095 | AE32: 0.13492258 | AF32: 758.20031 | AG32: 118.20155 | AH32: 632.81601 | AI32: 234.58495 | AJ32: 0.52247 | AK32: 258.8068 | AM32: 113.24753 | AN32: 694 | AO32: 0 | AP32: 248 | AQ32: 2841 | AR32: 463 | AS32: 96 | AT32: 12 | AU32: 54 | AV32: 0.52851 | AW32: 1.44645 | AX32: 4.97914 | AY32: BORALDES | AZ32: BORALDE_CENTRE | BA32: 196.42534
A33: F29 | B33: 46128 | C33: Gabin Laville | D33: 690019.73 | E33: 6381273.1 | F33: 3 | G33: 26.916553 | H33: 512 | I33: 6 | K33: FI | L33: 5 | M33: 5 | N33: 1 | O33: 0 | P33: 0 | Q33: 0 | R33: 0 | S33: 0 | T33: 0 | U33: Nord | V33: Sud | W33: Est | X33: FEU | Y33: FEU | Z33: =IF(ISNUMBER(MATCH(A33, TABLEAU_Floristique!B$1:DC$1, 0)), "OUI","NON") -> OUI | AB33: 0.46446 | AC33: 0.35308 | AD33: 0.50091821 | AE33: 0.60942908 | AF33: 286.90187 | AG33: 263.16908 | AH33: 1904.7 | AI33: 75.160603 | AJ33: 0.23153 | AK33: 211.59887 | AL33: 698.14682 | AM33: 3783.0855 | AN33: 667 | AO33: 0 | AP33: 267 | AQ33: 2799 | AR33: 517 | AS33: 100 | AT33: 15 | AU33: 58 | AV33: 0.52851 | AW33: 1.44645 | AX33: 4.97914 | AY33: BORALDES | AZ33: BORALDE_CENTRE | BA33: 53.777444
A34: F3 | B34: 46122 | C34: Gabin Laville | D34: 686331.47 | E34: 6408208.6 | F34: 2 | G34: 322.125 | H34: 984 | I34: 5 | K34: FR | L34: 5 | M34: 2 | N34: 5 | O34: 0 | P34: 0 | Q34: 0 | R34: 0 | S34: 0 | T34: 0 | U34: Nord | V34: Sud | W34: Est | X34: HET | Y34: HET | Z34: =IF(ISNUMBER(MATCH(A34, TABLEAU_Floristique!B$1:DC$1, 0)), "OUI","NON") -> OUI | AB34: 0.86361 | AC34: 0.4937 | AD34: 0.1707054 | AE34: 0.56712822 | AF34: 1253.3565 | AG34: 332.26159 | AH34: 19004.302 | AI34: 590.58128 | AJ34: 0.34542 | AK34: 849.44391 | AN34: 800 | AO34: 0 | AP34: 178 | AQ34: 2958 | AR34: 494 | AS34: 73 | AT34: 3 | AU34: 36 | AV34: 0.72789 | AW34: 0.0065 | AX34: 0.05199 | AY34: AUTRE | AZ34: VIADENE | BA34: 136.88495
A35: F30 | B35: 46141 | C35: Gabin Laville | D35: 689779.92 | E35: 6380027.6 | F35: 4 | G35: 88.264297 | H35: 493 | I35: 5 | J35: 19 | K35: T | L35: 5 | M35: 5 | N35: 2 | O35: 0 | P35: 0 | Q35: 0 | R35: 0 | S35: 0 | T35: 0 | U35: Nord | V35: Sud | W35: Est | X35: FEU | Y35: FEU | Z35: =IF(ISNUMBER(MATCH(A35, TABLEAU_Floristique!B$1:DC$1, 0)), "OUI","NON") -> OUI | AB35: 0.54161 | AC35: 0.44297 | AD35: 0.45721892 | AE35: 0.51669898 | AF35: 493.07734 | AG35: 224.4438 | AH35: 2225.7848 | AI35: 427.52402 | AJ35: 0.19939 | AK35: 208.51504 | AL35: 726.66016 | AM35: 2793.7336 | AN35: 664 | AO35: 0 | AP35: 269 | AQ35: 2794 | AR35: 549 | AS35: 101 | AT35: 16 | AU35: 59 | AV35: 0.52851 | AW35: 1.44645 | AX35: 4.97914 | AY35: BORALDES | AZ35: BORALDE_CENTRE | BA35: 73.84068
A36: F31 | B36: 46141 | C36: Gabin Laville | D36: 689372.79 | E36: 6379576.9 | F36: 3 | G36: 255.96376 | H36: 484 | I36: 3 | J36: 19 | K36: FI | L36: 5 | M36: 4 | N36: 5 | O36: 0 | P36: 0 | Q36: 0 | R36: 0 | S36: 0 | T36: 0 | U36: Nord | V36: Sud | W36: Est | X36: FEU | Y36: FEU | Z36: =IF(ISNUMBER(MATCH(A36, TABLEAU_Floristique!B$1:DC$1, 0)), "OUI","NON") -> OUI | AB36: 0.4636 | AC36: 0.45223 | AD36: 0.50450854 | AE36: 0.49000421 | AF36: 264.84236 | AG36: 201.88565 | AH36: 2148.3613 | AI36: 313.3658 | AJ36: 0.09657 | AK36: 248.06784 | AL36: 0.83957 | AM36: 5583.5848 | AN36: 664 | AO36: 0 | AP36: 269 | AQ36: 2815 | AR36: 549 | AS36: 101 | AT36: 16 | AU36: 59 | AV36: 0.52851 | AW36: 1.44645 | AX36: 4.97914 | AY36: BORALDES | AZ36: BORALDE_CENTRE | BA36: 53.186124
A37: F32 | B37: 46141 | C37: Gabin Laville | D37: 691265.26 | E37: 6381583.1 | F37: 4 | G37: 315 | H37: 531 | I37: 5 | J37: 26 | K37: T | L37: 5 | M37: 4 | N37: 2 | O37: 0 | P37: 0 | Q37: 0 | R37: 0 | S37: 0 | T37: 0 | U37: Nord | V37: Sud | W37: Est | X37: CHA | Y37: FEU | Z37: =IF(ISNUMBER(MATCH(A37, TABLEAU_Floristique!B$1:DC$1, 0)), "OUI","NON") -> OUI | AB37: 0.63988 | AC37: 0.58135 | AD37: 0.32199885 | AE37: 0.36864456 | AF37: 30.998249 | AG37: 233.31694 | AH37: 2721.3189 | AI37: 104.50954 | AJ37: 0.20516 | AK37: 130.51981 | AL37: 211.83153 | AM37: 7070.3848 | AN37: 668 | AO37: 0 | AP37: 254 | AQ37: 2779 | AR37: 523 | AS37: 102 | AT37: 9 | AU37: 57 | AV37: 0.52851 | AW37: 1.44645 | AX37: 4.97914 | AY37: BORALDES | AZ37: BORALDE_CENTRE | BA37: 73.414703
A38: F33 | B38: 46128 | C38: Gabin Laville | D38: 693165.86 | E38: 6382070 | F38: 5 | G38: 90.498215 | H38: 635 | I38: 4 | K38: FR | L38: 5 | M38: 2 | N38: 2 | O38: 1 | P38: 0 | Q38: 0 | R38: 1 | S38: 0 | T38: 0 | U38: Nord | V38: Sud | W38: Est | X38: PIN | Y38: CON | Z38: =IF(ISNUMBER(MATCH(A38, TABLEAU_Floristique!B$1:DC$1, 0)), "OUI","NON") -> OUI | AB38: 0.96381 | AC38: 0.75998 | AD38: 0.055644607 | AE38: 0.21949678 | AF38: 1142.8735 | AG38: 48.595754 | AH38: 3303.0684 | AI38: 58.632842 | AJ38: 0.21304 | AK38: 166.46122 | AL38: 597.45662 | AM38: 996.94207 | AN38: 674 | AO38: 0 | AP38: 237 | AQ38: 2745 | AR38: 565 | AS38: 95 | AT38: 6 | AU38: 51 | AV38: 0.52851 | AW38: 1.44645 | AX38: 4.97914 | AY38: BORALDES | AZ38: BORALDE_CENTRE | BA38: 152.85758
A39: F34 | B39: 46128 | C39: Gabin Laville | D39: 689040.94 | E39: 6380515 | F39: 2 | G39: 14.743561 | H39: 519 | I39: 7 | K39: FI | L39: 5 | M39: 3 | N39: 3 | O39: 0 | P39: 0 | Q39: 0 | R39: 1 | S39: 0 | T39: 0 | U39: Nord | V39: Sud | W39: Est | X39: CHE | Y39: FEU | Z39: =IF(ISNUMBER(MATCH(A39, TABLEAU_Floristique!B$1:DC$1, 0)), "OUI","NON") -> OUI | AB39: 0.22137 | AC39: 0.12799 | AD39: 0.73962321 | AE39: 0.80732224 | AF39: 217.89541 | AG39: 255.41425 | AH39: 1349.9273 | AI39: 391.0558 | AK39: 291.55151 | AM39: 6405.5041 | AN39: 666 | AO39: 0 | AP39: 274 | AQ39: 2817 | AR39: 534 | AS39: 102 | AT39: 17 | AU39: 61 | AV39: 0.52851 | AW39: 1.44645 | AX39: 4.97914 | AY39: BORALDES | AZ39: BORALDE_CENTRE | BA39: 40.217016
A40: F35 | B40: 46127 | C40: Gabin Laville | D40: 690821.8 | E40: 6382835 | F40: 4 | G40: 256.07904 | H40: 660 | I40: 6 | K40: MTF | L40: 5 | M40: 4 | N40: 2 | O40: 0 | P40: 0 | Q40: 0 | R40: 0 | S40: 0 | T40: 0 | U40: Nord | V40: Sud | W40: Est | X40: CHA | Y40: FEU | Z40: =IF(ISNUMBER(MATCH(A40, TABLEAU_Floristique!B$1:DC$1, 0)), "OUI","NON") -> OUI | AB40: 0.53283 | AC40: 0.44457 | AD40: 0.43945427 | AE40: 0.53167402 | AF40: 681.42296 | AG40: 80.718784 | AH40: 1663.9151 | AI40: 236.09024 | AJ40: 0.26407 | AK40: 75.132217 | AL40: 79.7231 | AM40: 3304.921 | AN40: 681 | AO40: 0 | AP40: 248 | AQ40: 2782 | AR40: 483 | AS40: 87 | AT40: 12 | AU40: 50 | AV40: 0.52851 | AW40: 1.44645 | AX40: 4.97914 | AY40: BORALDES | AZ40: BORALDE_CENTRE | BA40: 31.520165
...

Sheet SAISIE_Abroutissement
A1: Placette | B1: Sous-placette | C1: Espèce | D1: Taux de recouvrement | E1: Taux d'abroutissement
A2: F4 | B2: F4_1 | C2: Fraxinus excelsior | D2: 2 | E2: A
A3: F4 | B3: F4_1 | C3: Fagus sylvatica | D3: 4 | E3: O
A4: F4 | B4: F4_1 | C4: Ribes alpinum | D4: 4 | E4: O
A5: F4 | B5: F4_1 | C5: Ilex aquifolium | D5: 3 | E5: O
A6: F4 | B6: F4_1 | C6: Rosa sp.. | D6: 1 | E6: O
A7: F4 | B7: F4_2 | C7: Fraxinus excelsior | D7: 4 | E7: A
A8: F4 | B8: F4_2 | C8: Rubus fruticosus | D8: 5 | E8: O
A9: F4 | B9: F4_2 | C9: Lonicera periclymenum | D9: 2 | E9: A
A10: F4 | B10: F4_2 | C10: Fagus sylvatica | D10: 2 | E10: O
A11: F4 | B11: F4_2 | C11: Quercus petraea | D11: 3 | E11: O
A12: F4 | B12: F4_3 | C12: Fagus sylvatica | D12: 4 | E12: A
A13: F4 | B13: F4_3 | C13: Lonicera periclymenum | D13: 3 | E13: A
... A966: F67 | B966: F67_3 | C966: Fagus sylvatica | D966: 3 | E966: C

Sheet TABLEAU_Floristique
B1: F101 | C1: F100 | D1: F99 | E1: F98 | F1: F102 | G1: F103 | H1: F74 | I1: F81 | J1: F75 | K1: F44 | L1: F45 | M1: F96 | N1: F93 | O1: F94 | P1: F92 | Q1: F26bis | R1: F24 | S1: F22bis | T1: F22 | U1: F25 | V1: F32 | W1: F33 | X1: F35 | Y1: F86 | Z1: F83 | AA1: F87 | AB1: F85 | AC1: F95 | AD1: F60 | AE1: F61 | AF1: F50 | AG1: F20 | AH1: F23 | AI1: F17 | AJ1: F11 | AK1: F14 | AL1: F13 | AM1: F12 | AN1: F80 | AO1: F76 | AP1: F73 | AQ1: F84 | AR1: F37 | AS1: F34 | AT1: F105 | AU1: F18 | AV1: F10 | AW1: F2 | AX1: F3 | AY1: F1 | AZ1: F21 | BA1: F27 | BB1: F29 | BC1: F28 | BD1: F52 | BE1: F49 | BF1: F51 | BG1: F54 | BH1: F53 | BI1: F39 | BJ1: F38 | BK1: F56 | BL1: F31 | BM1: F30 | BN1: F43 | BO1: F63 | BP1: F48 | BQ1: F62 | BR1: F69 | BS1: F59 | BT1: F57 | BU1: F58 | BV1: F79 | BW1: F78 | BX1: F5 | BY1: F6 | BZ1: F66 | CA1: F67 | CB1: F91 | CC1: F77 | CD1: F88 | CE1: F89 | CF1: F90 | CG1: F106 | CH1: F8 | CI1: F9 | CJ1: F40 | CK1: F36 | CL1: F36bis | CM1: F71 | CN1: F72 | CO1: F82 | CP1: F19 | CQ1: F4 | CR1: F7 | CS1: F55 | CT1: F97 | CU1: F46 | CV1: F47 | CW1: F64 | CX1: F42 | CY1: F41 | CZ1: F104 | DA1: F107bis | DB1: F15 | DC1: F16
A2: Abies alba A | B2: 0 | C2: 0 | D2: 0 | E2: 0 | F2: 0 | G2: 0 | H2: 0 | I2: 0 | J2: 0 | K2: 0 | L2: 0 | M2: 0 | N2: 0 | O2: 0 | P2: 0 | Q2: 0 | R2: 0 | S2: 0 | T2: 0 | U2: 0 | V2: 0 | W2: 0 | X2: 0 | Y2: 2 | Z2: 4 | AA2: 2 | AB2: 0 | AC2: 0 | AD2: 0 | AE2: 0 | AF2: 0 | AG2: 0 | AH2: 0 | AI2: 0 | AJ2: 0 | AK2: 0 | AL2: 0 | AM2: 0 | AN2: 0 | AO2: 0 | AP2: 0 | AQ2: 0 | AR2: 0 | AS2: 0 | AT2: 0 | AU2: 2 | AV2: 0 | AW2: 4 | AX2: 0 | AY2: 0 | AZ2: 0 | BA2: 0 | BB2: 0 | BC2: 0 | BD2: 0 | BE2: 0 | BF2: 0 | BG2: 0 | BH2: 0 | BI2: 0 | BJ2: 0 | BK2: 3 | BL2: 0 | BM2: 0 | BN2: 0 | BO2: 0 | BP2: 0 | BQ2: 0 | BR2: 0 | BS2: 0 | BT2: 0 | BU2: 0 | BV2: 0 | BW2: 0 | BX2: 2 | BY2: 4 | BZ2: 0 | CA2: 0 | CB2: 3 | CC2: 0 | CD2: 2 | CE2: 4 | CF2: 0 | CG2: 3 | CH2: 0 | CI2: 0 | CJ2: 0 | CK2: 0 | CL2: 0 | CM2: 0 | CN2: 0 | CO2: 0 | CP2: 0 | CQ2: 0 | CR2: 0 | CS2: 0 | CT2: 0 | CU2: 0 | CV2: 0 | CW2: 0 | CX2: 0 | CY2: 0 | CZ2: 0 | DA2: 0 | DB2: 0 | DC2: 0
A3: Abies alba a | B3: 0 | C3: 0 | D3: 3 | E3: 0 | F3: 0 | G3: 0 | H3: 1 | I3: 0 | J3: 0 | K3: 0 | L3: 0 | M3: 0 | N3: 0 | O3: 0 | P3: 0 | Q3: 0 | R3: 0 | S3: 0 | T3: 0 | U3: 0 | V3: 0 | W3: 0 | X3: 0 | Y3: 0 | Z3: 0 | AA3: 0 | AB3: 0 | AC3: 0 | AD3: 0 | AE3: 0 | AF3: 0 | AG3: 0 | AH3: 0 | AI3: 0 | AJ3: 0 | AK3: 0 | AL3: 0 | AM3: 0 | AN3: 1 | AO3: 0 | AP3: 0 | AQ3: 0 | AR3: 0 | AS3: 0 | AT3: 0 | AU3: 2 | AV3: 0 | AW3: 3 | AX3: 0 | AY3: 0 | AZ3: 0 | BA3: 0 | BB3: 0 | BC3: 0 | BD3: 0 | BE3: 0 | BF3: 0 | BG3: 0 | BH3: 0 | BI3: 0 | BJ3: 0 | BK3: 2 | BL3: 0 | BM3: 0 | BN3: 0 | BO3: 0 | BP3: 0 | BQ3: 0 | BR3: 0 | BS3: 0 | BT3: 0 | BU3: 0 | BV3: 0 | BW3: 0 | BX3: 2 | BY3: 3 | BZ3: 0 | CA3: 0 | CB3: 2 | CC3: 0 | CD3: 2 | CE3: 2 | CF3: 0 | CG3: 2 | CH3: 1 | CI3: 0 | CJ3: 0 | CK3: 0 | CL3: 0 | CM3: 0 | CN3: 0 | CO3: 0 | CP3: 0 | CQ3: 0 | CR3: 0 | CS3: 2 | CT3: 0 | CU3: 0 | CV3: 0 | CW3: 0 | CX3: 0 | CY3: 0 | CZ3: 0 | DA3: 0 | DB3: 0 | DC3: 0
A4: Abies alba h | B4: 0.5 | C4: 0 | D4: 1 | E4: 0 | F4: 0 | G4: 0 | H4: 0 | I4: 0 | J4: 0 | K4: 0 | L4: 0 | M4: 0 | N4: 0 | O4: 0 | P4: 0 | Q4: 0 | R4: 0 | S4: 0 | T4: 0 | U4: 0 | V4: 0 | W4: 0.5 | X4: 0 | Y4: 0 | Z4: 0.5 | AA4: 0.5 | AB4: 0 | AC4: 0 | AD4: 0 | AE4: 0 | AF4: 0 | AG4: 0 | AH4: 0 | AI4: 0 | AJ4: 0 | AK4: 0 | AL4: 0 | AM4: 0 | AN4: 0 | AO4: 0 | AP4: 0 | AQ4: 0 | AR4: 0 | AS4: 0 | AT4: 0 | AU4: 0.5 | AV4: 0 | AW4: 0.5 | AX4: 0 | AY4: 0 | AZ4: 0 | BA4: 0 | BB4: 0 | BC4: 0 | BD4: 0 | BE4: 0 | BF4: 0 | BG4: 0 | BH4: 0 | BI4: 0 | BJ4: 0 | BK4: 3 | BL4: 0 | BM4: 0 | BN4: 0 | BO4: 1 | BP4: 0 | BQ4: 0 | BR4: 0 | BS4: 0 | BT4: 0 | BU4: 0 | BV4: 0 | BW4: 0 | BX4: 0.5 | BY4: 1 | BZ4: 0 | CA4: 0 | CB4: 0 | CC4: 0 | CD4: 0.5 | CE4: 0.5 | CF4: 0 | CG4: 0.5 | CH4: 1 | CI4: 0 | CJ4: 0 | CK4: 0 | CL4: 0 | CM4: 0 | CN4: 0 | CO4: 0 | CP4: 0 | CQ4: 0 | CR4: 0 | CS4: 1 | CT4: 0 | CU4: 0.5 | CV4: 0 | CW4: 0 | CX4: 0 | CY4: 0 | CZ4: 0 | DA4: 0 | DB4: 0 | DC4: 0
A5: Acer campestre A | B5: 0 | C5: 0 | D5: 0 | E5: 0 | F5: 0 | G5: 0 | H5: 0 | I5: 0 | J5: 0 | K5: 0 | L5: 0 | M5: 0 | N5: 0 | O5: 0 | P5: 0 | Q5: 0 | R5: 0 | S5: 0 | T5: 0 | U5: 0 | V5: 0 | W5: 0 | X5: 0 | Y5: 0 | Z5: 0 | AA5: 0 | AB5: 0 | AC5: 0 | AD5: 0 | AE5: 0 | AF5: 0 | AG5: 0 | AH5: 0 | AI5: 0 | AJ5: 0 | AK5: 0 | AL5: 0 | AM5: 0 | AN5: 0 | AO5: 0 | AP5: 0 | AQ5: 0 | AR5: 0 | AS5: 0 | AT5: 0 | AU5: 0 | AV5: 0 | AW5: 0 | AX5: 0 | AY5: 0 | AZ5: 0 | BA5: 0 | BB5: 0 | BC5: 0 | BD5: 0 | BE5: 0 | BF5: 0 | BG5: 0 | BH5: 0 | BI5: 0 | BJ5: 0 | BK5: 0 | BL5: 0 | BM5: 0 | BN5: 0 | BO5: 0 | BP5: 0 | BQ5: 0 | BR5: 0 | BS5: 0 | BT5: 0 | BU5: 0 | BV5: 0 | BW5: 0 | BX5: 0 | BY5: 0 | BZ5: 0 | CA5: 0 | CB5: 0 | CC5: 0 | CD5: 0 | CE5: 0 | CF5: 0 | CG5: 0 | CH5: 0 | CI5: 0 | CJ5: 0 | CK5: 0 | CL5: 0 | CM5: 0 | CN5: 0 | CO5: 0 | CP5: 0 | CQ5: 0 | CR5: 0 | CS5: 0 | CT5: 0 | CU5: 0 | CV5: 0 | CW5: 0 | CX5: 0 | CY5: 0 | CZ5: 0 | DA5: 0 | DB5: 0 | DC5: 0
A6: Acer campestre a | B6: 0 | C6: 0 | D6: 0 | E6: 0 | F6: 0 | G6: 0 | H6: 0 | I6: 0 | J6: 0 | K6: 0 | L6: 0 | M6: 0 | N6: 0 | O6: 0 | P6: 0 | Q6: 0 | R6: 0 | S6: 0 | T6: 0 | U6: 0 | V6: 0 | W6: 0 | X6: 0 | Y6: 0 | Z6: 0 | AA6: 0 | AB6: 0 | AC6: 0 | AD6: 0 | AE6: 0 | AF6: 0 | AG6: 0 | AH6: 0 | AI6: 0 | AJ6: 0 | AK6: 0 | AL6: 0 | AM6: 0 | AN6: 0 | AO6: 0 | AP6: 0 | AQ6: 0 | AR6: 0 | AS6: 1 | AT6: 0 | AU6: 0 | AV6: 0 | AW6: 0 | AX6: 0 | AY6: 0 | AZ6: 0 | BA6: 0 | BB6: 0 | BC6: 0 | BD6: 0 | BE6: 0 | BF6: 0 | BG6: 0 | BH6: 0 | BI6: 0 | BJ6: 0 | BK6: 0 | BL6: 0 | BM6: 0 | BN6: 0 | BO6: 0 | BP6: 0 | BQ6: 0 | BR6: 0 | BS6: 0 | BT6: 0 | BU6: 0 | BV6: 0 | BW6: 0 | BX6: 0 | BY6: 0 | BZ6: 0 | CA6: 0 | CB6: 0 | CC6: 0 | CD6: 0 | CE6: 0 | CF6: 0 | CG6: 0 | CH6: 0 | CI6: 0 | CJ6: 0 | CK6: 0 | CL6: 0 | CM6: 0 | CN6: 0 | CO6: 0 | CP6: 0 | CQ6: 0 | CR6: 0 | CS6: 0 | CT6: 0 | CU6: 0 | CV6: 0 | CW6: 0 | CX6: 0 | CY6: 0 | CZ6: 0 | DA6: 0 | DB6: 0 | DC6: 0
A7: Acer campestre h | B7: 0 | C7: 0 | D7: 0 | E7: 0 | F7: 0 | G7: 0 | H7: 0 | I7: 0 | J7: 0 | K7: 0 | L7: 0 | M7: 0 | N7: 0 | O7: 0 | P7: 0 | Q7: 0 | R7: 0 | S7: 0 | T7: 0 | U7: 0 | V7: 0.5 | W7: 0 | X7: 0 | Y7: 0 | Z7: 0 | AA7: 0 | AB7: 0 | AC7: 0 | AD7: 0 | AE7: 0 | AF7: 0 | AG7: 0 | AH7: 0 | AI7: 0 | AJ7: 0 | AK7: 0 | AL7: 0 | AM7: 0 | AN7: 0 | AO7: 0 | AP7: 0 | AQ7: 0 | AR7: 0.5 | AS7: 0.5 | AT7: 0.5 | AU7: 0 | AV7: 0 | AW7: 0 | AX7: 0 | AY7: 0 | AZ7: 0 | BA7: 0 | BB7: 0 | BC7: 0 | BD7: 0 | BE7: 0 | BF7: 0 | BG7: 0 | BH7: 0 | BI7: 0 | BJ7: 0 | BK7: 0 | BL7: 0 | BM7: 0 | BN7: 0 | BO7: 0 | BP7: 0 | BQ7: 0 | BR7: 0 | BS7: 0 | BT7: 0 | BU7: 0 | BV7: 0 | BW7: 0 | BX7: 0 | BY7: 0 | BZ7: 0 | CA7: 0 | CB7: 0 | CC7: 0 | CD7: 0 | CE7: 0 | CF7: 0 | CG7: 0 | CH7: 0 | CI7: 0 | CJ7: 0 | CK7: 0 | CL7: 0 | CM7: 0 | CN7: 0 | CO7: 0 | CP7: 0 | CQ7: 0 | CR7: 0 | CS7: 0 | CT7: 0 | CU7: 0.5 | CV7: 0 | CW7: 0 | CX7: 0 | CY7: 0 | CZ7: 0 | DA7: 0 | DB7: 0 | DC7: 0
A8: Acer platanoides A | B8: 0 | C8: 0 | D8: 0 | E8: 0 | F8: 0 | G8: 0 | H8: 0 | I8: 0 | J8: 0 | K8: 0 | L8: 0 | M8: 0 | N8: 0 | O8: 0 | P8: 0 | Q8: 0 | R8: 0 | S8: 0 | T8: 0 | U8: 0 | V8: 0 | W8: 0 | X8: 0 | Y8: 0 | Z8: 0 | AA8: 0 | AB8: 0 | AC8: 0 | AD8: 0 | AE8: 0 | AF8: 0 | AG8: 0 | AH8: 0 | AI8: 0 | AJ8: 0 | AK8: 0 | AL8: 0 | AM8: 0 | AN8: 0 | AO8: 0 | AP8: 0 | AQ8: 0 | AR8: 0 | AS8: 0 | AT8: 0 | AU8: 0 | AV8: 0 | AW8: 0 | AX8: 0 | AY8: 0 | AZ8: 0 | BA8: 0 | BB8: 0 | BC8: 0 | BD8: 0 | BE8: 0 | BF8: 0 | BG8: 0 | BH8: 0 | BI8: 0 | BJ8: 0 | BK8: 0 | BL8: 0 | BM8: 0 | BN8: 0 | BO8: 0 | BP8: 0 | BQ8: 0 | BR8: 0 | BS8: 0 | BT8: 0 | BU8: 0 | BV8: 0 | BW8: 0 | BX8: 0 | BY8: 0 | BZ8: 0 | CA8: 0 | CB8: 0 | CC8: 0 | CD8: 0 | CE8: 0 | CF8: 0 | CG8: 0 | CH8: 3 | CI8: 0 | CJ8: 0 | CK8: 0 | CL8: 0 | CM8: 0 | CN8: 0 | CO8: 0 | CP8: 0 | CQ8: 0 | CR8: 0 | CS8: 0 | CT8: 0 | CU8: 0 | CV8: 0 | CW8: 0 | CX8: 0 | CY8: 0 | CZ8: 0 | DA8: 0 | DB8: 0 | DC8: 0
A9: Acer platanoides a | B9: 0 | C9: 0 | D9: 0 | E9: 0 | F9: 0 | G9: 0 | H9: 0 | I9: 0 | J9: 0 | K9: 0 | L9: 0 | M9: 0 | N9: 0 | O9: 0 | P9: 0 | Q9: 0 | R9: 0 | S9: 0 | T9: 0 | U9: 0 | V9: 0 | W9: 0 | X9: 0 | Y9: 0 | Z9: 0 | AA9: 0 | AB9: 0 | AC9: 0 | AD9: 0 | AE9: 0 | AF9: 0 | AG9: 0 | AH9: 0 | AI9: 0 | AJ9: 0 | AK9: 0 | AL9: 0 | AM9: 0 | AN9: 0 | AO9: 0 | AP9: 0 | AQ9: 0 | AR9: 0 | AS9: 0 | AT9: 0 | AU9: 0 | AV9: 0 | AW9: 0 | AX9: 0 | AY9: 0 | AZ9: 0 | BA9: 0 | BB9: 0 | BC9: 0 | BD9: 0 | BE9: 0 | BF9: 0 | BG9: 0 | BH9: 0 | BI9: 0 | BJ9: 0 | BK9: 0 | BL9: 0 | BM9: 0 | BN9: 0 | BO9: 0 | BP9: 0 | BQ9: 0 | BR9: 0 | BS9: 0 | BT9: 0 | BU9: 0 | BV9: 0 | BW9: 0 | BX9: 0 | BY9: 0 | BZ9: 0 | CA9: 0 | CB9: 0 | CC9: 0 | CD9: 0 | CE9: 0 | CF9: 0 | CG9: 0 | CH9: 2 | CI9: 0 | CJ9: 0 | CK9: 0 | CL9: 0 | CM9: 0 | CN9: 0 | CO9: 0 | CP9: 0 | CQ9: 0 | CR9: 0 | CS9: 0 | CT9: 0 | CU9: 0 | CV9: 0 | CW9: 0 | CX9: 0 | CY9: 0 | CZ9: 0 | DA9: 0 | DB9: 0 | DC9: 0
A10: Acer platanoides h | B10: 0 | C10: 0 | D10: 0 | E10: 0 | F10: 0 | G10: 0 | H10: 0 | I10: 0 | J10: 0 | K10: 0 | L10: 0 | M10: 0 | N10: 0 | O10: 0 | P10: 0 | Q10: 0 | R10: 0 | S10: 0 | T10: 0 | U10: 0 | V10: 0 | W10: 0 | X10: 0 | Y10: 0 | Z10: 0 | AA10: 0 | AB10: 0 | AC10: 0 | AD10: 0 | AE10: 0 | AF10: 0 | AG10: 0 | AH10: 0 | AI10: 0 | AJ10: 0 | AK10: 0 | AL10: 1 | AM10: 1 | AN10: 0 | AO10: 0 | AP10: 0 | AQ10: 0 | AR10: 0 | AS10: 0 | AT10: 0 | AU10: 0 | AV10: 0 | AW10: 0 | AX10: 0 | AY10: 0 | AZ10: 0 | BA10: 0 | BB10: 0 | BC10: 0 | BD10: 0 | BE10: 0 | BF10: 0 | BG10: 0 | BH10: 0 | BI10: 0 | BJ10: 0 | BK10: 0 | BL10: 0 | BM10: 0 | BN10: 0 | BO10: 0 | BP10: 0 | BQ10: 0 | BR10: 0 | BS10: 0 | BT10: 0 | BU10: 0 | BV10: 0 | BW10: 0 | BX10: 0 | BY10: 0 | BZ10: 0 | CA10: 0 | CB10: 0 | CC10: 0 | CD10: 0 | CE10: 0 | CF10: 0 | CG10: 0 | CH10: 0.5 | CI10: 0 | CJ10: 0 | CK10: 0 | CL10: 0.5 | CM10: 0 | CN10: 0 | CO10: 0 | CP10: 0 | CQ10: 0 | CR10: 0 | CS10: 0 | CT10: 0 | CU10: 0 | CV10: 0 | CW10: 0 | CX10: 0 | CY10: 0 | CZ10: 0 | DA10: 0 | DB10: 0 | DC10: 0
A11: Acer pseudoplatanus A | B11: 0 | C11: 0 | D11: 0 | E11: 0 | F11: 0 | G11: 0 | H11: 0 | I11: 0 | J11: 0 | K11: 0 | L11: 0 | M11: 0 | N11: 0 | O11: 0 | P11: 0 | Q11: 0 | R11: 0 | S11: 0 | T11: 0 | U11: 0 | V11: 0 | W11: 0 | X11: 0 | Y11: 0 | Z11: 0 | AA11: 0 | AB11: 0 | AC11: 0 | AD11: 0 | AE11: 0 | AF11: 0 | AG11: 0 | AH11: 0 | AI11: 0 | AJ11: 0 | AK11: 0 | AL11: 2 | AM11: 3 | AN11: 0 | AO11: 0 | AP11: 0 | AQ11: 0 | AR11: 0 | AS11: 0 | AT11: 0 | AU11: 0 | AV11: 0 | AW11: 0 | AX11: 0 | AY11: 0 | AZ11: 0 | BA11: 0 | BB11: 0 | BC11: 0 | BD11: 0 | BE11: 0 | BF11: 0 | BG11: 0 | BH11: 0 | BI11: 0 | BJ11: 0 | BK11: 0 | BL11: 0 | BM11: 0 | BN11: 0 | BO11: 0 | BP11: 0 | BQ11: 0 | BR11: 0 | BS11: 0 | BT11: 0 | BU11: 0 | BV11: 0 | BW11: 0 | BX11: 0 | BY11: 0 | BZ11: 0 | CA11: 0 | CB11: 0 | CC11: 0 | CD11: 0 | CE11: 0 | CF11: 0 | CG11: 0 | CH11: 0 | CI11: 0 | CJ11: 0 | CK11: 0 | CL11: 0 | CM11: 0 | CN11: 0 | CO11: 0 | CP11: 0 | CQ11: 0 | CR11: 0 | CS11: 0 | CT11: 0 | CU11: 0 | CV11: 0 | CW11: 0 | CX11: 0 | CY11: 0 | CZ11: 0 | DA11: 0 | DB11: 0 | DC11: 0
A12: Acer pseudoplatanus a | B12: 1 | C12: 0 | D12: 0 | E12: 0 | F12: 0 | G12: 0 | H12: 0 | I12: 0 | J12: 0 | K12: 0 | L12: 0 | M12: 0 | N12: 0 | O12: 0 | P12: 0 | Q12: 0 | R12: 0 | S12: 0 | T12: 0 | U12: 0 | V12: 0 | W12: 0 | X12: 0 | Y12: 0 | Z12: 0 | AA12: 0 | AB12: 0 | AC12: 0 | AD12: 0 | AE12: 0 | AF12: 0 | AG12: 0 | AH12: 0 | AI12: 0 | AJ12: 0 | AK12: 0 | AL12: 0 | AM12: 0 | AN12: 0 | AO12: 0 | AP12: 0 | AQ12: 0 | AR12: 0 | AS12: 0 | AT12: 0 | AU12: 0 | AV12: 0 | AW12: 0 | AX12: 0 | AY12: 0 | AZ12: 0 | BA12: 0 | BB12: 0 | BC12: 0 | BD12: 0 | BE12: 0 | BF12: 0 | BG12: 0 | BH12: 0 | BI12: 0 | BJ12: 0 | BK12: 0 | BL12: 0 | BM12: 0 | BN12: 0 | BO12: 0 | BP12: 0 | BQ12: 0 | BR12: 1 | BS12: 0 | BT12: 0 | BU12: 0 | BV12: 0 | BW12: 0 | BX12: 0 | BY12: 0 | BZ12: 0 | CA12: 0 | CB12: 0 | CC12: 0 | CD12: 0 | CE12: 0 | CF12: 0 | CG12: 0 | CH12: 0 | CI12: 0 | CJ12: 0 | CK12: 0 | CL12: 0 | CM12: 0 | CN12: 1 | CO12: 0 | CP12: 0 | CQ12: 0 | CR12: 0 | CS12: 0 | CT12: 0 | CU12: 0 | CV12: 0 | CW12: 0 | CX12: 0 | CY12: 0 | CZ12: 0 | DA12: 0 | DB12: 0 | DC12: 0
A13: Acer pseudoplatanus h | B13: 2 | C13: 0 | D13: 0 | E13: 0 | F13: 0 | G13: 0 | H13: 0 | I13: 0 | J13: 0 | K13: 0 | L13: 0 | M13: 0 | N13: 0 | O13: 0 | P13: 0 | Q13: 0 | R13: 0 | S13: 0 | T13: 0 | U13: 0 | V13: 0 | W13: 0 | X13: 0 | Y13: 0 | Z13: 0 | AA13: 0 | AB13: 0 | AC13: 0 | AD13: 0 | AE13: 0 | AF13: 0 | AG13: 0 | AH13: 0 | AI13: 0 | AJ13: 0 | AK13: 0 | AL13: 0 | AM13: 0 | AN13: 0 | AO13: 0 | AP13: 0 | AQ13: 0 | AR13: 0 | AS13: 0 | AT13: 0 | AU13: 0 | AV13: 0 | AW13: 0 | AX13: 0 | AY13: 0 | AZ13: 0 | BA13: 0 | BB13: 0 | BC13: 0 | BD13: 0 | BE13: 0 | BF13: 0 | BG13: 0 | BH13: 0 | BI13: 0 | BJ13: 0 | BK13: 0 | BL13: 0 | BM13: 0 | BN13: 0 | BO13: 0 | BP13: 0 | BQ13: 0 | BR13: 0 | BS13: 0 | BT13: 0 | BU13: 0 | BV13: 0 | BW13: 0 | BX13: 0 | BY13: 0 | BZ13: 0 | CA13: 0 | CB13: 0 | CC13: 0 | CD13: 0 | CE13: 0 | CF13: 0 | CG13: 0 | CH13: 0.5 | CI13: 0 | CJ13: 0 | CK13: 0 | CL13: 0 | CM13: 0.5 | CN13: 0 | CO13: 0 | CP13: 0 | CQ13: 0 | CR13: 0 | CS13: 0 | CT13: 0 | CU13: 0 | CV13: 0 | CW13: 0 | CX13: 0 | CY13: 0 | CZ13: 0 | DA13: 0 | DB13: 0 | DC13: 0
... A244: Viola sp | B244: 0 | C244: 0 | D244: 0 | E244: 0.5 | F244: 0 | G244: 0 | H244: 1 | I244: 0 | J244: 1 | K244: 0 | L244: 0.5 | M244: 0 | N244: 0.5 | O244: 0 | P244: 0 | Q244: 1 | R244: 0 | S244: 0.5 | T244: 1 | U244: 0.5 | V244: 0 | W244: 0.5 | X244: 0 | Y244: 0.5 | Z244: 3 | AA244: 1 | AB244: 0.5 | AC244: 0.5 | AD244: 0 | AE244: 0 | AF244: 0.5 | AG244: 0 | AH244: 0.5 | AI244: 0.5 | AJ244: 0.5 | AK244: 0 | AL244: 0 | AM244: 0 | AN244: 0.5 | AO244: 0.5 | AP244: 0 | AQ244: 0.5 | AR244: 0 | AS244: 0 | AT244: 0.5 | AU244: 0 | AV244: 0 | AW244: 0 | AX244: 0 | AY244: 0 | AZ244: 0 | BA244: 0 | BB244: 0 | BC244: 0 | BD244: 0 | BE244: 0 | BF244: 0 | BG244: 0 | BH244: 0 | BI244: 0 | BJ244: 0 | BK244: 0 | BL244: 0 | BM244: 0 | BN244: 0 | BO244: 0 | BP244: 0 | BQ244: 0 | BR244: 0 | BS244: 0 | BT244: 0 | BU244: 0 | BV244: 0.5 | BW244: 0 | BX244: 0 | BY244: 0 | BZ244: 0 | CA244: 0 | CB244: 0 | CC244: 0.5 | CD244: 0.5 | CE244: 0.5 | CF244: 0.5 | CG244: 0.5 | CH244: 0 | CI244: 0.5 | CJ244: 0 | CK244: 0.5 | CL244: 0.5 | CM244: 0 | CN244: 0 | CO244: 0 | CP244: 0 | CQ244: 0 | CR244: 0 | CS244: 0 | CT244: 0 | CU244: 0 | CV244: 0 | CW244: 0 | CX244: 0 | CY244: 0 | CZ244: 0 | DA244: 0 | DB244: 0 | DC244: 0

Sheet CALCUL_Taux
A1: Classe | B1: Taux de recouvrement | D1: Classe | E1: Taux d'abroutissement | G1: Coefficient abondance-dominance | H1: Recouvrement
A2: 1 | B2: 0 < R < 1% | D2: O | E2: 0 < A < 1% | G2: r | H2: <5%, très peu d'individus
A3: 2 | B3: 1 < R < 5% | D3: A | E3: 1 < A < 5% | G3: + | H3: <5%, peu d'individus
A4: 3 | B4: 5 < R < 20% | D4: B | E4: 5 < A < 20% | G4: 1 | H4: <5%, nombreux individus
A5: 4 | B5: 20 < R < 50% | D5: C | E5: 20 < A < 50% | G5: 2 | H5: 5 à 25%
A6: 5 | B6: 50 < R < 75% | D6: D | E6: 50 < A < 75% | G6: 3 | H6: 25 à 50%
A7: 6 | B7: 75 < R < 100% | D7: E | E7: 75 < A < 100% | G7: 4 | H7: 50 à 75%
G8: 5 | H8: 75 à 100%

Sheet CALCUL_Ligneux
A1: lib_cdref | B1: cd_ref | C1: lib_vern | D1: espar
A2: Abies alba | B2: 79319 | C2: Sapin pectiné | D2: 61
A3: Abies bornmuelleriana | B3: 79323 | C3: Sapin de Turquie | D3: 70SB
A4: Abies cephalonica | B4: 79325 | C4: Sapin de Céphalonie | D4: 70SC
A5: Abies cilicica | B5: 717025 | C5: Sapin de Cilicie | D5: 68SI
A6: Abies concolor | B6: 79327 | C6: Sapin du Colorado | D6: 68SC
A7: Abies grandis | B7: 79333 | C7: Sapin de Vancouver | D7: 72V
A8: Abies nordmanniana | B8: 79345 | C8: Sapin de Nordmann | D8: 71
A9: Abies pinsapo | B9: 79349 | C9: Sapin d'Andalousie | D9: 70SE
A10: Abies procera | B10: 79350 | C10: Sapin noble | D10: 72N
A11: Acer campestre | B11: 79734 | C11: Érable champêtre | D11: 21C
A12: Acer monspessulanum | B12: 79763 | C12: Érable de Montpellier | D12: 21M
A13: Acer negundo | B13: 79766 | C13: Érable negundo | D13: 29EN
... A27: Buxus sempervirens | B27: 87143 | C27: Buis | D27: 49BS
A28: Calluna vulgaris | B28: 96700 | C28: Callune
A29: Carpinus betulus | B29: 89200 | C29: Charme | D29: 11
A30: Castanea sativa | B30: 89304 | C30: Châtaignier | D30: 10
A31: Casuarina cunninghamiana | B31: 89308 | C31: Filao | D31: 29FI
A32: Catalpa bignonioides | B32: 89323 | C32: Catalpa | D32: 29CT
A33: Cedrus atlantica | B33: 89452 | C33: Cèdre de l'Atlas | D33: 65
A34: Cedrus deodara | B34: 89454 | C34: Cèdre de l'Himalaya | D34: 68CH
A35: Cedrus libani | B35: 89455 | C35: Cèdre du Liban | D35: 76
A36: Cedrus libani var. brevifolia | B36: 621117 | C36: Cèdre de Chypre | D36: 68CB
A37: Celtis australis | B37: 89468 | C37: Micocoulier | D37: 16
A38: Ceratonia siliqua | B38: 447038 | C38: Caroubier | D38: 29CA
A39: Cercis siliquastrum | B39: 90234 | C39: Arbre de Judée | D39: 49CS
A40: Chamaecyparis lawsoniana | B40: 90411 | C40: Cyprès de Lawson | D40: 68CL
... A44: Cornus mas | B44: 92497 | C44: Cornouiller mâle | D44: 39
A45: Cornus sanginea | B45: 92501 | C45: Cornouiller sanguin
A46: Corylus avellana | B46: 92606 | C46: Noisetier coudrier | D46: 31
A47: Crataegus azarolus | B47: 92824 | C47: Aubépine azérolier | D47: 49AA
A48: Crataegus laevigata | B48: 92864 | C48: Aubépine épineuse | D48: 49AE
A49: Crataegus monogyna | B49: 92876 | C49: Aubépine monogyne | D49: 49AM
A50: Cryptomeria japonica | B50: 93471 | C50: Cryptomère du Japon | D50: 68CJ
A51: Cupressus arizonica | B51: 93570 | C51: Cyprès de l'Arizona | D51: 68CA
A52: Cupressus macrocarpa | B52: 93585 | C52: Cyprès de Lambert | D52: 68CM
A53: Cupressus sempervirens | B53: 93590 | C53: Cyprès de Provence | D53: 66
A54: Cydonia oblonga | B54: 93734 | C54: Cognassier | D54: 49C
A55: Cytisus scoparius | B55: 124467 | C55: Genêt à balais
A56: Daphne mezereum | B56: 94435 | C56: Bois-joli
...

Sheet CLASSES_Structure
A1: Code | B1: Libellé | D1: Code | E1: Peuplement | G1: Code | H1: Catégorie de peuplement
A2: T | B2: Taillis | D2: HET | E2: Hêtre | G2: HET | H2: Hêtraie / Hêtraie-sapinière montagnarde
A3: MTF | B3: Mélange taillis-futaie | D3: CHE | E3: Chêne | G3: FEU | H3: Peuplements de feuillus mixtes (chênaie / hêtraie à mélange de frêne et de chataîgnier) des vallées et versants
A4: FI | B4: Futaie irrégulière | D4: CHA | E4: Châtaignier | G4: CON | H4: Peuplements d'autres conifères (pin sylvestre, épicéa, mélèze)
A5: FR | B5: Futaie régulière | D5: FEU | E5: Mélange de feuillus
A6: A | B6: Autres | D6: SAP | E6: Sapin
D7: EPI | E7: Épicéa
D8: PIN | E8: Pin
D9: MEL | E9: Mélèze
D10: DOU | E10: Douglas
D11: CON | E11: Mélange de conifères
D12: MIX | E12: Mixte feuillus et conifères
